Workbook

Sheet northwind_orders
A1: order_id | B1: customer_id | C1: employee_id | D1: order_date | E1: required_date | F1: shipped_date | G1: ship_via | H1: freight | I1: ship_name | J1: ship_address | K1: ship_city | L1: ship_region | M1: ship_postal_code | N1: ship_country | O1: delivery
A2: 10248 | B2: VINET | C2: 5 | D2: 35250 | E2: 35278 | F2: 35262 | G2: 3 | H2: 32.38 | I2: Vins et alcools Chevalier | J2: 59 rue de l'Abbaye | K2: Reims | M2: 51100 | N2: France | O2: =IF(northwind_orders[[#This Row],[required_date]]-northwind_orders[[#This Row],[shipped_date]]>0,"Faster",IF(northwind_orders[[#This Row],[required_date]]-northwind_orders[[#This Row],[shipped_date]]=0,"In Time","Slower")) -> Faster
A3: 10249 | B3: TOMSP | C3: 6 | D3: 35251 | E3: 35293 | F3: 35256 | G3: 1 | H3: 11.61 | I3: Toms SpezialitГ¤ten | J3: Luisenstr. 48 | K3: MГјnster | M3: 44087 | N3: Germany | O3: =IF(northwind_orders[[#This Row],[required_date]]-northwind_orders[[#This Row],[shipped_date]]>0,"Faster",IF(northwind_orders[[#This Row],[required_date]]-northwind_orders[[#This Row],[shipped_date]]=0,"In Time","Slower")) -> Faster
A4: 10250 | B4: HANAR | C4: 4 | D4: 35254 | E4: 35282 | F4: 35258 | G4: 2 | H4: 65.83 | I4: Hanari Carnes | J4: Rua do PaГ§o, 67 | K4: Rio de Janeiro | L4: RJ | M4: 05454-876 | N4: Brazil | O4: =IF(northwind_orders[[#This Row],[required_date]]-northwind_orders[[#This Row],[shipped_date]]>0,"Faster",IF(northwind_orders[[#This Row],[required_date]]-northwind_orders[[#This Row],[shipped_date]]=0,"In Time","Slower")) -> Faster
A5: 10251 | B5: VICTE | C5: 3 | D5: 35254 | E5: 35282 | F5: 35261 | G5: 1 | H5: 41.34 | I5: Victuailles en stock | J5: 2, rue du Commerce | K5: Lyon | M5: 69004 | N5: France | O5: =IF(northwind_orders[[#This Row],[required_date]]-northwind_orders[[#This Row],[shipped_date]]>0,"Faster",IF(northwind_orders[[#This Row],[required_date]]-northwind_orders[[#This Row],[shipped_date]]=0,"In Time","Slower")) -> Faster
A6: 10252 | B6: SUPRD | C6: 4 | D6: 35255 | E6: 35283 | F6: 35257 | G6: 2 | H6: 51.3 | I6: SuprГЄmes dГ©lices | J6: Boulevard Tirou, 255 | K6: Charleroi | M6: B-6000 | N6: Belgium | O6: =IF(northwind_orders[[#This Row],[required_date]]-northwind_orders[[#This Row],[shipped_date]]>0,"Faster",IF(northwind_orders[[#This Row],[required_date]]-northwind_orders[[#This Row],[shipped_date]]=0,"In Time","Slower")) -> Faster
A7: 10253 | B7: HANAR | C7: 3 | D7: 35256 | E7: 35270 | F7: 35262 | G7: 2 | H7: 58.17 | I7: Hanari Carnes | J7: Rua do PaГ§o, 67 | K7: Rio de Janeiro | L7: RJ | M7: 05454-876 | N7: Brazil | O7: =IF(northwind_orders[[#This Row],[required_date]]-northwind_orders[[#This Row],[shipped_date]]>0,"Faster",IF(northwind_orders[[#This Row],[required_date]]-northwind_orders[[#This Row],[shipped_date]]=0,"In Time","Slower")) -> Faster
A8: 10254 | B8: CHOPS | C8: 5 | D8: 35257 | E8: 35285 | F8: 35269 | G8: 2 | H8: 22.98 | I8: Chop-suey Chinese | J8: Hauptstr. 31 | K8: Bern | M8: 3012 | N8: Switzerland | O8: =IF(northwind_orders[[#This Row],[required_date]]-northwind_orders[[#This Row],[shipped_date]]>0,"Faster",IF(northwind_orders[[#This Row],[required_date]]-northwind_orders[[#This Row],[shipped_date]]=0,"In Time","Slower")) -> Faster
A9: 10255 | B9: RICSU | C9: 9 | D9: 35258 | E9: 35286 | F9: 35261 | G9: 3 | H9: 148.33 | I9: Richter Supermarkt | J9: Starenweg 5 | K9: GenГЁve | M9: 1204 | N9: Switzerland | O9: =IF(northwind_orders[[#This Row],[required_date]]-northwind_orders[[#This Row],[shipped_date]]>0,"Faster",IF(northwind_orders[[#This Row],[required_date]]-northwind_orders[[#This Row],[shipped_date]]=0,"In Time","Slower")) -> Faster
A10: 10256 | B10: WELLI | C10: 3 | D10: 35261 | E10: 35289 | F10: 35263 | G10: 2 | H10: 13.97 | I10: Wellington Importadora | J10: Rua do Mercado, 12 | K10: Resende | L10: SP | M10: 08737-363 | N10: Brazil | O10: =IF(northwind_orders[[#This Row],[required_date]]-northwind_orders[[#This Row],[shipped_date]]>0,"Faster",IF(northwind_orders[[#This Row],[required_date]]-northwind_orders[[#This Row],[shipped_date]]=0,"In Time","Slower")) -> Faster
A11: 10257 | B11: HILAA | C11: 4 | D11: 35262 | E11: 35290 | F11: 35268 | G11: 3 | H11: 81.91 | I11: HILARION-Abastos | J11: Carrera 22 con Ave. Carlos Soublette #8-35 | K11: San CristГіbal | L11: TГЎchira | M11: 5022 | N11: Venezuela | O11: =IF(northwind_orders[[#This Row],[required_date]]-northwind_orders[[#This Row],[shipped_date]]>0,"Faster",IF(northwind_orders[[#This Row],[required_date]]-northwind_orders[[#This Row],[shipped_date]]=0,"In Time","Slower")) -> Faster
A12: 10258 | B12: ERNSH | C12: 1 | D12: 35263 | E12: 35291 | F12: 35269 | G12: 1 | H12: 140.51 | I12: Ernst Handel | J12: Kirchgasse 6 | K12: Graz | M12: 8010 | N12: Austria | O12: =IF(northwind_orders[[#This Row],[required_date]]-northwind_orders[[#This Row],[shipped_date]]>0,"Faster",IF(northwind_orders[[#This Row],[required_date]]-northwind_orders[[#This Row],[shipped_date]]=0,"In Time","Slower")) -> Faster
A13: 10259 | B13: CENTC | C13: 4 | D13: 35264 | E13: 35292 | F13: 35271 | G13: 3 | H13: 3.25 | I13: Centro comercial Moctezuma | J13: Sierras de Granada 9993 | K13: MГ©xico D.F. | M13: 05022 | N13: Mexico | O13: =IF(northwind_orders[[#This Row],[required_date]]-northwind_orders[[#This Row],[shipped_date]]>0,"Faster",IF(northwind_orders[[#This Row],[required_date]]-northwind_orders[[#This Row],[shipped_date]]=0,"In Time","Slower")) -> Faster
A14: 10260 | B14: OTTIK | C14: 4 | D14: 35265 | E14: 35293 | F14: 35275 | G14: 1 | H14: 55.09 | I14: Ottilies KГ¤seladen | J14: Mehrheimerstr. 369 | K14: KГ¶ln | M14: 50739 | N14: Germany | O14: =IF(northwind_orders[[#This Row],[required_date]]-northwind_orders[[#This Row],[shipped_date]]>0,"Faster",IF(northwind_orders[[#This Row],[required_date]]-northwind_orders[[#This Row],[shipped_date]]=0,"In Time","Slower")) -> Faster
A15: 10261 | B15: QUEDE | C15: 4 | D15: 35265 | E15: 35293 | F15: 35276 | G15: 2 | H15: 3.05 | I15: Que DelГ­cia | J15: Rua da Panificadora, 12 | K15: Rio de Janeiro | L15: RJ | M15: 02389-673 | N15: Brazil | O15: =IF(northwind_orders[[#This Row],[required_date]]-northwind_orders[[#This Row],[shipped_date]]>0,"Faster",IF(northwind_orders[[#This Row],[required_date]]-northwind_orders[[#This Row],[shipped_date]]=0,"In Time","Slower")) -> Faster
A16: 10262 | B16: RATTC | C16: 8 | D16: 35268 | E16: 35296 | F16: 35271 | G16: 3 | H16: 48.29 | I16: Rattlesnake Canyon Grocery | J16: 2817 Milton Dr. | K16: Albuquerque | L16: NM | M16: 87110 | N16: USA | O16: =IF(northwind_orders[[#This Row],[required_date]]-northwind_orders[[#This Row],[shipped_date]]>0,"Faster",IF(northwind_orders[[#This Row],[required_date]]-northwind_orders[[#This Row],[shipped_date]]=0,"In Time","Slower")) -> Faster
A17: 10263 | B17: ERNSH | C17: 9 | D17: 35269 | E17: 35297 | F17: 35277 | G17: 3 | H17: 146.06 | I17: Ernst Handel | J17: Kirchgasse 6 | K17: Graz | M17: 8010 | N17: Austria | O17: =IF(northwind_orders[[#This Row],[required_date]]-northwind_orders[[#This Row],[shipped_date]]>0,"Faster",IF(northwind_orders[[#This Row],[required_date]]-northwind_orders[[#This Row],[shipped_date]]=0,"In Time","Slower")) -> Faster
A18: 10264 | B18: FOLKO | C18: 6 | D18: 35270 | E18: 35298 | F18: 35300 | G18: 3 | H18: 3.67 | I18: Folk och fГ¤ HB | J18: Г…kergatan 24 | K18: BrГ¤cke | M18: S-844 67 | N18: Sweden | O18: =IF(northwind_orders[[#This Row],[required_date]]-northwind_orders[[#This Row],[shipped_date]]>0,"Faster",IF(northwind_orders[[#This Row],[required_date]]-northwind_orders[[#This Row],[shipped_date]]=0,"In Time","Slower")) -> Slower
A19: 10265 | B19: BLONP | C19: 2 | D19: 35271 | E19: 35299 | F19: 35289 | G19: 1 | H19: 55.28 | I19: Blondel pГЁre et fils | J19: 24, place KlГ©ber | K19: Strasbourg | M19: 67000 | N19: France | O19: =IF(northwind_orders[[#This Row],[required_date]]-northwind_orders[[#This Row],[shipped_date]]>0,"Faster",IF(northwind_orders[[#This Row],[required_date]]-northwind_orders[[#This Row],[shipped_date]]=0,"In Time","Slower")) -> Faster
A20: 10266 | B20: WARTH | C20: 3 | D20: 35272 | E20: 35314 | F20: 35277 | G20: 3 | H20: 25.73 | I20: Wartian Herkku | J20: Torikatu 38 | K20: Oulu | M20: 90110 | N20: Finland | O20: =IF(northwind_orders[[#This Row],[required_date]]-northwind_orders[[#This Row],[shipped_date]]>0,"Faster",IF(northwind_orders[[#This Row],[required_date]]-northwind_orders[[#This Row],[shipped_date]]=0,"In Time","Slower")) -> Faster
A21: 10267 | B21: FRANK | C21: 4 | D21: 35275 | E21: 35303 | F21: 35283 | G21: 1 | H21: 208.58 | I21: Frankenversand | J21: Berliner Platz 43 | K21: MГјnchen | M21: 80805 | N21: Germany | O21: =IF(northwind_orders[[#This Row],[required_date]]-northwind_orders[[#This Row],[shipped_date]]>0,"Faster",IF(northwind_orders[[#This Row],[required_date]]-northwind_orders[[#This Row],[shipped_date]]=0,"In Time","Slower")) -> Faster
A22: 10268 | B22: GROSR | C22: 8 | D22: 35276 | E22: 35304 | F22: 35279 | G22: 3 | H22: 66.29 | I22: GROSELLA-Restaurante | J22: 5ВЄ Ave. Los Palos Grandes | K22: Caracas | L22: DF | M22: 1081 | N22: Venezuela | O22: =IF(northwind_orders[[#This Row],[required_date]]-northwind_orders[[#This Row],[shipped_date]]>0,"Faster",IF(northwind_orders[[#This Row],[required_date]]-northwind_orders[[#This Row],[shipped_date]]=0,"In Time","Slower")) -> Faster
A23: 10269 | B23: WHITC | C23: 5 | D23: 35277 | E23: 35291 | F23: 35286 | G23: 1 | H23: 4.56 | I23: White Clover Markets | J23: 1029 - 12th Ave. S. | K23: Seattle | L23: WA | M23: 98124 | N23: USA | O23: =IF(northwind_orders[[#This Row],[required_date]]-northwind_orders[[#This Row],[shipped_date]]>0,"Faster",IF(northwind_orders[[#This Row],[required_date]]-northwind_orders[[#This Row],[shipped_date]]=0,"In Time","Slower")) -> Faster
A24: 10270 | B24: WARTH | C24: 1 | D24: 35278 | E24: 35306 | F24: 35279 | G24: 1 | H24: 136.54 | I24: Wartian Herkku | J24: Torikatu 38 | K24: Oulu | M24: 90110 | N24: Finland | O24: =IF(northwind_orders[[#This Row],[required_date]]-northwind_orders[[#This Row],[shipped_date]]>0,"Faster",IF(northwind_orders[[#This Row],[required_date]]-northwind_orders[[#This Row],[shipped_date]]=0,"In Time","Slower")) -> Faster
A25: 10271 | B25: SPLIR | C25: 6 | D25: 35278 | E25: 35306 | F25: 35307 | G25: 2 | H25: 4.54 | I25: Split Rail Beer & Ale | J25: P.O. Box 555 | K25: Lander | L25: WY | M25: 82520 | N25: USA | O25: =IF(northwind_orders[[#This Row],[required_date]]-northwind_orders[[#This Row],[shipped_date]]>0,"Faster",IF(northwind_orders[[#This Row],[required_date]]-northwind_orders[[#This Row],[shipped_date]]=0,"In Time","Slower")) -> Slower
A26: 10272 | B26: RATTC | C26: 6 | D26: 35279 | E26: 35307 | F26: 35283 | G26: 2 | H26: 98.03 | I26: Rattlesnake Canyon Grocery | J26: 2817 Milton Dr. | K26: Albuquerque | L26: NM | M26: 87110 | N26: USA | O26: =IF(northwind_orders[[#This Row],[required_date]]-northwind_orders[[#This Row],[shipped_date]]>0,"Faster",IF(northwind_orders[[#This Row],[required_date]]-northwind_orders[[#This Row],[shipped_date]]=0,"In Time","Slower")) -> Faster
A27: 10273 | B27: QUICK | C27: 3 | D27: 35282 | E27: 35310 | F27: 35289 | G27: 3 | H27: 76.07 | I27: QUICK-Stop | J27: TaucherstraГџe 10 | K27: Cunewalde | M27: 01307 | N27: Germany | O27: =IF(northwind_orders[[#This Row],[required_date]]-northwind_orders[[#This Row],[shipped_date]]>0,"Faster",IF(northwind_orders[[#This Row],[required_date]]-northwind_orders[[#This Row],[shipped_date]]=0,"In Time","Slower")) -> Faster
A28: 10274 | B28: VINET | C28: 6 | D28: 35283 | E28: 35311 | F28: 35293 | G28: 1 | H28: 6.01 | I28: Vins et alcools Chevalier | J28: 59 rue de l'Abbaye | K28: Reims | M28: 51100 | N28: France | O28: =IF(northwind_orders[[#This Row],[required_date]]-northwind_orders[[#This Row],[shipped_date]]>0,"Faster",IF(northwind_orders[[#This Row],[required_date]]-northwind_orders[[#This Row],[shipped_date]]=0,"In Time","Slower")) -> Faster
A29: 10275 | B29: MAGAA | C29: 1 | D29: 35284 | E29: 35312 | F29: 35286 | G29: 1 | H29: 26.93 | I29: Magazzini Alimentari Riuniti | J29: Via Ludovico il Moro 22 | K29: Bergamo | M29: 24100 | N29: Italy | O29: =IF(northwind_orders[[#This Row],[required_date]]-northwind_orders[[#This Row],[shipped_date]]>0,"Faster",IF(northwind_orders[[#This Row],[required_date]]-northwind_orders[[#This Row],[shipped_date]]=0,"In Time","Slower")) -> Faster
A30: 10276 | B30: TORTU | C30: 8 | D30: 35285 | E30: 35299 | F30: 35291 | G30: 3 | H30: 13.84 | I30: Tortuga Restaurante | J30: Avda. Azteca 123 | K30: MГ©xico D.F. | M30: 05033 | N30: Mexico | O30: =IF(northwind_orders[[#This Row],[required_date]]-northwind_orders[[#This Row],[shipped_date]]>0,"Faster",IF(northwind_orders[[#This Row],[required_date]]-northwind_orders[[#This Row],[shipped_date]]=0,"In Time","Slower")) -> Faster
A31: 10277 | B31: MORGK | C31: 2 | D31: 35286 | E31: 35314 | F31: 35290 | G31: 3 | H31: 125.77 | I31: Morgenstern Gesundkost | J31: Heerstr. 22 | K31: Leipzig | M31: 04179 | N31: Germany | O31: =IF(northwind_orders[[#This Row],[required_date]]-northwind_orders[[#This Row],[shipped_date]]>0,"Faster",IF(northwind_orders[[#This Row],[required_date]]-northwind_orders[[#This Row],[shipped_date]]=0,"In Time","Slower")) -> Faster
A32: 10278 | B32: BERGS | C32: 8 | D32: 35289 | E32: 35317 | F32: 35293 | G32: 2 | H32: 92.69 | I32: Berglunds snabbkГ¶p | J32: BerguvsvГ¤gen 8 | K32: LuleГҐ | M32: S-958 22 | N32: Sweden | O32: =IF(northwind_orders[[#This Row],[required_date]]-northwind_orders[[#This Row],[shipped_date]]>0,"Faster",IF(northwind_orders[[#This Row],[required_date]]-northwind_orders[[#This Row],[shipped_date]]=0,"In Time","Slower")) -> Faster
A33: 10279 | B33: LEHMS | C33: 8 | D33: 35290 | E33: 35318 | F33: 35293 | G33: 2 | H33: 25.83 | I33: Lehmanns Marktstand | J33: Magazinweg 7 | K33: Frankfurt a.M. | M33: 60528 | N33: Germany | O33: =IF(northwind_orders[[#This Row],[required_date]]-northwind_orders[[#This Row],[shipped_date]]>0,"Faster",IF(northwind_orders[[#This Row],[required_date]]-northwind_orders[[#This Row],[shipped_date]]=0,"In Time","Slower")) -> Faster
A34: 10280 | B34: BERGS | C34: 2 | D34: 35291 | E34: 35319 | F34: 35320 | G34: 1 | H34: 8.98 | I34: Berglunds snabbkГ¶p | J34: BerguvsvГ¤gen 8 | K34: LuleГҐ | M34: S-958 22 | N34: Sweden | O34: =IF(northwind_orders[[#This Row],[required_date]]-northwind_orders[[#This Row],[shipped_date]]>0,"Faster",IF(northwind_orders[[#This Row],[required_date]]-northwind_orders[[#This Row],[shipped_date]]=0,"In Time","Slower")) -> Slower
A35: 10281 | B35: ROMEY | C35: 4 | D35: 35291 | E35: 35305 | F35: 35298 | G35: 1 | H35: 2.94 | I35: Romero y tomillo | J35: Gran VГ­a, 1 | K35: Madrid | M35: 28001 | N35: Spain | O35: =IF(northwind_orders[[#This Row],[required_date]]-northwind_orders[[#This Row],[shipped_date]]>0,"Faster",IF(northwind_orders[[#This Row],[required_date]]-northwind_orders[[#This Row],[shipped_date]]=0,"In Time","Slower")) -> Faster
A36: 10282 | B36: ROMEY | C36: 4 | D36: 35292 | E36: 35320 | F36: 35298 | G36: 1 | H36: 12.69 | I36: Romero y tomillo | J36: Gran VГ­a, 1 | K36: Madrid | M36: 28001 | N36: Spain | O36: =IF(northwind_orders[[#This Row],[required_date]]-northwind_orders[[#This Row],[shipped_date]]>0,"Faster",IF(northwind_orders[[#This Row],[required_date]]-northwind_orders[[#This Row],[shipped_date]]=0,"In Time","Slower")) -> Faster
A37: 10283 | B37: LILAS | C37: 3 | D37: 35293 | E37: 35321 | F37: 35300 | G37: 3 | H37: 84.81 | I37: LILA-Supermercado | J37: Carrera 52 con Ave. BolГ­var #65-98 Llano Largo | K37: Barquisimeto | L37: Lara | M37: 3508 | N37: Venezuela | O37: =IF(northwind_orders[[#This Row],[required_date]]-northwind_orders[[#This Row],[shipped_date]]>0,"Faster",IF(northwind_orders[[#This Row],[required_date]]-northwind_orders[[#This Row],[shipped_date]]=0,"In Time","Slower")) -> Faster
A38: 10284 | B38: LEHMS | C38: 4 | D38: 35296 | E38: 35324 | F38: 35304 | G38: 1 | H38: 76.56 | I38: Lehmanns Marktstand | J38: Magazinweg 7 | K38: Frankfurt a.M. | M38: 60528 | N38: Germany | O38: =IF(northwind_orders[[#This Row],[required_date]]-northwind_orders[[#This Row],[shipped_date]]>0,"Faster",IF(northwind_orders[[#This Row],[required_date]]-northwind_orders[[#This Row],[shipped_date]]=0,"In Time","Slower")) -> Faster
A39: 10285 | B39: QUICK | C39: 1 | D39: 35297 | E39: 35325 | F39: 35303 | G39: 2 | H39: 76.83 | I39: QUICK-Stop | J39: TaucherstraГџe 10 | K39: Cunewalde | M39: 01307 | N39: Germany | O39: =IF(northwind_orders[[#This Row],[required_date]]-northwind_orders[[#This Row],[shipped_date]]>0,"Faster",IF(northwind_orders[[#This Row],[required_date]]-northwind_orders[[#This Row],[shipped_date]]=0,"In Time","Slower")) -> Faster
A40: 10286 | B40: QUICK | C40: 8 | D40: 35298 | E40: 35326 | F40: 35307 | G40: 3 | H40: 229.24 | I40: QUICK-Stop | J40: TaucherstraГџe 10 | K40: Cunewalde | M40: 01307 | N40: Germany | O40: =IF(northwind_orders[[#This Row],[required_date]]-northwind_orders[[#This Row],[shipped_date]]>0,"Faster",IF(northwind_orders[[#This Row],[required_date]]-northwind_orders[[#This Row],[shipped_date]]=0,"In Time","Slower")) -> Faster
...

Sheet northwind_order_details
A1: order_id | B1: product_id | C1: unit_price | D1: quantity | E1: discount | F1: country | G1: Employee Id | H1: purchase amount | I1: discount amount | J1: Revenue | K1: discount check | L1: Type of Revenue | M1: Price reconciliation | O1: Country | P1: Total Revenue | Q1: Average purchase | R1: Number of orders | S1: Discount Leakage | T1: High | U1: Medium | V1: Low | W1: Match | X1: Mismatch
A2: 10248 | B2: 11 | C2: 14 | D2: 12 | E2: 0 | F2: =_xlfn.XLOOKUP(northwind_order_details[[#This Row],[order_id]],northwind_orders[order_id],northwind_orders[ship_country]) -> France | G2: =INDEX(northwind_orders[],MATCH(northwind_order_details[[#This Row],[order_id]], northwind_orders[order_id], 0), MATCH("employee_id", northwind_orders[#Headers], 0)) -> 5 | H2: =northwind_order_details[[#This Row],[unit_price]]*northwind_order_details[[#This Row],[quantity]] -> 168 | I2: =northwind_order_details[[#This Row],[purchase amount]]*northwind_order_details[[#This Row],[discount]] -> 0 | J2: =northwind_order_details[[#This Row],[purchase amount]]-northwind_order_details[[#This Row],[discount amount]] -> 168 | K2: =IF(northwind_order_details[[#This Row],[discount amount]]>0,"Yes","No") -> No | L2: =IF(northwind_order_details[[#This Row],[Revenue]]>1000,"High",IF(northwind_order_details[[#This Row],[Revenue]]>300,"Medium","Low")) -> Low | M2: =IF(northwind_order_details[[#This Row],[unit_price]]=_xlfn.XLOOKUP(northwind_order_details[[#This Row],[product_id]],'Price Validation'!$D$2:$D$78,'Price Validation'!$E$2:$E$78),"Match","Mismatch") -> Mismatch | O2: {=_xlfn.UNIQUE(northwind_order_details[country])} -> France | P2: =SUMIF(northwind_order_details[country],$O2,northwind_order_details[Revenue]) -> 80529.572 | Q2: =AVERAGEIF(northwind_order_details[country],$O2,northwind_order_details[Revenue]) -> 447.38651 | R2: =COUNTIF(northwind_order_details[country],O2) -> 180 | S2: =ROUND(SUMIF(northwind_order_details[country],$O2,northwind_order_details[discount amount]),2) -> 3867.19 | T2: =COUNTIFS(northwind_order_details[Type of Revenue],T$1,northwind_order_details[country],$O2) -> 21 | U2: =COUNTIFS(northwind_order_details[Type of Revenue],U$1,northwind_order_details[country],$O2) -> 58 | V2: =COUNTIFS(northwind_order_details[Type of Revenue],V$1,northwind_order_details[country],$O2) -> 101 | W2: =COUNTIFS(northwind_order_details[Price reconciliation],"Match",northwind_order_details[country],$O2) -> 53 | X2: =COUNTIFS(northwind_order_details[Price reconciliation],"Mismatch",northwind_order_details[country],$O2) -> 127
A3: 10248 | B3: 42 | C3: 9.8 | D3: 10 | E3: 0 | F3: =_xlfn.XLOOKUP(northwind_order_details[[#This Row],[order_id]],northwind_orders[order_id],northwind_orders[ship_country]) -> France | G3: =INDEX(northwind_orders[],MATCH(northwind_order_details[[#This Row],[order_id]], northwind_orders[order_id], 0), MATCH("employee_id", northwind_orders[#Headers], 0)) -> 5 | H3: =northwind_order_details[[#This Row],[unit_price]]*northwind_order_details[[#This Row],[quantity]] -> 98 | I3: =northwind_order_details[[#This Row],[purchase amount]]*northwind_order_details[[#This Row],[discount]] -> 0 | J3: =northwind_order_details[[#This Row],[purchase amount]]-northwind_order_details[[#This Row],[discount amount]] -> 98 | K3: =IF(northwind_order_details[[#This Row],[discount amount]]>0,"Yes","No") -> No | L3: =IF(northwind_order_details[[#This Row],[Revenue]]>1000,"High",IF(northwind_order_details[[#This Row],[Revenue]]>300,"Medium","Low")) -> Low | M3: =IF(northwind_order_details[[#This Row],[unit_price]]=_xlfn.XLOOKUP(northwind_order_details[[#This Row],[product_id]],'Price Validation'!$D$2:$D$78,'Price Validation'!$E$2:$E$78),"Match","Mismatch") -> Mismatch | O3: Germany | P3: =SUMIF(northwind_order_details[country],$O3,northwind_order_details[Revenue]) -> 227796.66 | Q3: =AVERAGEIF(northwind_order_details[country],$O3,northwind_order_details[Revenue]) -> 709.64691 | R3: =COUNTIF(northwind_order_details[country],O3) -> 321 | S3: =ROUND(SUMIF(northwind_order_details[country],$O3,northwind_order_details[discount amount]),2) -> 14112.47 | T3: =COUNTIFS(northwind_order_details[Type of Revenue],T$1,northwind_order_details[country],$O3) -> 61 | U3: =COUNTIFS(northwind_order_details[Type of Revenue],U$1,northwind_order_details[country],$O3) -> 142 | V3: =COUNTIFS(northwind_order_details[Type of Revenue],V$1,northwind_order_details[country],$O3) -> 118 | W3: =COUNTIFS(northwind_order_details[Price reconciliation],"Match",northwind_order_details[country],$O3) -> 108 | X3: =COUNTIFS(northwind_order_details[Price reconciliation],"Mismatch",northwind_order_details[country],$O3) -> 213
A4: 10248 | B4: 72 | C4: 34.8 | D4: 5 | E4: 0 | F4: =_xlfn.XLOOKUP(northwind_order_details[[#This Row],[order_id]],northwind_orders[order_id],northwind_orders[ship_country]) -> France | G4: =INDEX(northwind_orders[],MATCH(northwind_order_details[[#This Row],[order_id]], northwind_orders[order_id], 0), MATCH("employee_id", northwind_orders[#Headers], 0)) -> 5 | H4: =northwind_order_details[[#This Row],[unit_price]]*northwind_order_details[[#This Row],[quantity]] -> 174 | I4: =northwind_order_details[[#This Row],[purchase amount]]*northwind_order_details[[#This Row],[discount]] -> 0 | J4: =northwind_order_details[[#This Row],[purchase amount]]-northwind_order_details[[#This Row],[discount amount]] -> 174 | K4: =IF(northwind_order_details[[#This Row],[discount amount]]>0,"Yes","No") -> No | L4: =IF(northwind_order_details[[#This Row],[Revenue]]>1000,"High",IF(northwind_order_details[[#This Row],[Revenue]]>300,"Medium","Low")) -> Low | M4: =IF(northwind_order_details[[#This Row],[unit_price]]=_xlfn.XLOOKUP(northwind_order_details[[#This Row],[product_id]],'Price Validation'!$D$2:$D$78,'Price Validation'!$E$2:$E$78),"Match","Mismatch") -> Match | O4: Brazil | P4: =SUMIF(northwind_order_details[country],$O4,northwind_order_details[Revenue]) -> 103060.7 | Q4: =AVERAGEIF(northwind_order_details[country],$O4,northwind_order_details[Revenue]) -> 523.15074 | R4: =COUNTIF(northwind_order_details[country],O4) -> 197 | S4: =ROUND(SUMIF(northwind_order_details[country],$O4,northwind_order_details[discount amount]),2) -> 7684.98 | T4: =COUNTIFS(northwind_order_details[Type of Revenue],T$1,northwind_order_details[country],$O4) -> 21 | U4: =COUNTIFS(northwind_order_details[Type of Revenue],U$1,northwind_order_details[country],$O4) -> 73 | V4: =COUNTIFS(northwind_order_details[Type of Revenue],V$1,northwind_order_details[country],$O4) -> 103 | W4: =COUNTIFS(northwind_order_details[Price reconciliation],"Match",northwind_order_details[country],$O4) -> 62 | X4: =COUNTIFS(northwind_order_details[Price reconciliation],"Mismatch",northwind_order_details[country],$O4) -> 135
A5: 10249 | B5: 14 | C5: 18.6 | D5: 9 | E5: 0 | F5: =_xlfn.XLOOKUP(northwind_order_details[[#This Row],[order_id]],northwind_orders[order_id],northwind_orders[ship_country]) -> Germany | G5: =INDEX(northwind_orders[],MATCH(northwind_order_details[[#This Row],[order_id]], northwind_orders[order_id], 0), MATCH("employee_id", northwind_orders[#Headers], 0)) -> 6 | H5: =northwind_order_details[[#This Row],[unit_price]]*northwind_order_details[[#This Row],[quantity]] -> 167.4 | I5: =northwind_order_details[[#This Row],[purchase amount]]*northwind_order_details[[#This Row],[discount]] -> 0 | J5: =northwind_order_details[[#This Row],[purchase amount]]-northwind_order_details[[#This Row],[discount amount]] -> 167.4 | K5: =IF(northwind_order_details[[#This Row],[discount amount]]>0,"Yes","No") -> No | L5: =IF(northwind_order_details[[#This Row],[Revenue]]>1000,"High",IF(northwind_order_details[[#This Row],[Revenue]]>300,"Medium","Low")) -> Low | M5: =IF(northwind_order_details[[#This Row],[unit_price]]=_xlfn.XLOOKUP(northwind_order_details[[#This Row],[product_id]],'Price Validation'!$D$2:$D$78,'Price Validation'!$E$2:$E$78),"Match","Mismatch") -> Mismatch | O5: Belgium | P5: =SUMIF(northwind_order_details[country],$O5,northwind_order_details[Revenue]) -> 33824.855 | Q5: =AVERAGEIF(northwind_order_details[country],$O5,northwind_order_details[Revenue]) -> 604.01527 | R5: =COUNTIF(northwind_order_details[country],O5) -> 56 | S5: =ROUND(SUMIF(northwind_order_details[country],$O5,northwind_order_details[discount amount]),2) -> 1310.13 | T5: =COUNTIFS(northwind_order_details[Type of Revenue],T$1,northwind_order_details[country],$O5) -> 12 | U5: =COUNTIFS(northwind_order_details[Type of Revenue],U$1,northwind_order_details[country],$O5) -> 26 | V5: =COUNTIFS(northwind_order_details[Type of Revenue],V$1,northwind_order_details[country],$O5) -> 18 | W5: =COUNTIFS(northwind_order_details[Price reconciliation],"Match",northwind_order_details[country],$O5) -> 14 | X5: =COUNTIFS(northwind_order_details[Price reconciliation],"Mismatch",northwind_order_details[country],$O5) -> 42
A6: 10249 | B6: 51 | C6: 42.4 | D6: 40 | E6: 0 | F6: =_xlfn.XLOOKUP(northwind_order_details[[#This Row],[order_id]],northwind_orders[order_id],northwind_orders[ship_country]) -> Germany | G6: =INDEX(northwind_orders[],MATCH(northwind_order_details[[#This Row],[order_id]], northwind_orders[order_id], 0), MATCH("employee_id", northwind_orders[#Headers], 0)) -> 6 | H6: =northwind_order_details[[#This Row],[unit_price]]*northwind_order_details[[#This Row],[quantity]] -> 1696 | I6: =northwind_order_details[[#This Row],[purchase amount]]*northwind_order_details[[#This Row],[discount]] -> 0 | J6: =northwind_order_details[[#This Row],[purchase amount]]-northwind_order_details[[#This Row],[discount amount]] -> 1696 | K6: =IF(northwind_order_details[[#This Row],[discount amount]]>0,"Yes","No") -> No | L6: =IF(northwind_order_details[[#This Row],[Revenue]]>1000,"High",IF(northwind_order_details[[#This Row],[Revenue]]>300,"Medium","Low")) -> High | M6: =IF(northwind_order_details[[#This Row],[unit_price]]=_xlfn.XLOOKUP(northwind_order_details[[#This Row],[product_id]],'Price Validation'!$D$2:$D$78,'Price Validation'!$E$2:$E$78),"Match","Mismatch") -> Mismatch | O6: Switzerland | P6: =SUMIF(northwind_order_details[country],$O6,northwind_order_details[Revenue]) -> 31194.559 | Q6: =AVERAGEIF(northwind_order_details[country],$O6,northwind_order_details[Revenue]) -> 636.62365 | R6: =COUNTIF(northwind_order_details[country],O6) -> 49 | S6: =ROUND(SUMIF(northwind_order_details[country],$O6,northwind_order_details[discount amount]),2) -> 1138.94 | T6: =COUNTIFS(northwind_order_details[Type of Revenue],T$1,northwind_order_details[country],$O6) -> 9 | U6: =COUNTIFS(northwind_order_details[Type of Revenue],U$1,northwind_order_details[country],$O6) -> 26 | V6: =COUNTIFS(northwind_order_details[Type of Revenue],V$1,northwind_order_details[country],$O6) -> 14 | W6: =COUNTIFS(northwind_order_details[Price reconciliation],"Match",northwind_order_details[country],$O6) -> 18 | X6: =COUNTIFS(northwind_order_details[Price reconciliation],"Mismatch",northwind_order_details[country],$O6) -> 31
A7: 10250 | B7: 41 | C7: 7.7 | D7: 10 | E7: 0 | F7: =_xlfn.XLOOKUP(northwind_order_details[[#This Row],[order_id]],northwind_orders[order_id],northwind_orders[ship_country]) -> Brazil | G7: =INDEX(northwind_orders[],MATCH(northwind_order_details[[#This Row],[order_id]], northwind_orders[order_id], 0), MATCH("employee_id", northwind_orders[#Headers], 0)) -> 4 | H7: =northwind_order_details[[#This Row],[unit_price]]*northwind_order_details[[#This Row],[quantity]] -> 77 | I7: =northwind_order_details[[#This Row],[purchase amount]]*northwind_order_details[[#This Row],[discount]] -> 0 | J7: =northwind_order_details[[#This Row],[purchase amount]]-northwind_order_details[[#This Row],[discount amount]] -> 77 | K7: =IF(northwind_order_details[[#This Row],[discount amount]]>0,"Yes","No") -> No | L7: =IF(northwind_order_details[[#This Row],[Revenue]]>1000,"High",IF(northwind_order_details[[#This Row],[Revenue]]>300,"Medium","Low")) -> Low | M7: =IF(northwind_order_details[[#This Row],[unit_price]]=_xlfn.XLOOKUP(northwind_order_details[[#This Row],[product_id]],'Price Validation'!$D$2:$D$78,'Price Validation'!$E$2:$E$78),"Match","Mismatch") -> Mismatch | O7: Venezuela | P7: =SUMIF(northwind_order_details[country],$O7,northwind_order_details[Revenue]) -> 53046.709 | Q7: =AVERAGEIF(northwind_order_details[country],$O7,northwind_order_details[Revenue]) -> 482.24281 | R7: =COUNTIF(northwind_order_details[country],O7) -> 110 | S7: =ROUND(SUMIF(northwind_order_details[country],$O7,northwind_order_details[discount amount]),2) -> 3915.62 | T7: =COUNTIFS(northwind_order_details[Type of Revenue],T$1,northwind_order_details[country],$O7) -> 11 | U7: =COUNTIFS(northwind_order_details[Type of Revenue],U$1,northwind_order_details[country],$O7) -> 45 | V7: =COUNTIFS(northwind_order_details[Type of Revenue],V$1,northwind_order_details[country],$O7) -> 54 | W7: =COUNTIFS(northwind_order_details[Price reconciliation],"Match",northwind_order_details[country],$O7) -> 37 | X7: =COUNTIFS(northwind_order_details[Price reconciliation],"Mismatch",northwind_order_details[country],$O7) -> 73
A8: 10250 | B8: 51 | C8: 42.4 | D8: 35 | E8: 0.15 | F8: =_xlfn.XLOOKUP(northwind_order_details[[#This Row],[order_id]],northwind_orders[order_id],northwind_orders[ship_country]) -> Brazil | G8: =INDEX(northwind_orders[],MATCH(northwind_order_details[[#This Row],[order_id]], northwind_orders[order_id], 0), MATCH("employee_id", northwind_orders[#Headers], 0)) -> 4 | H8: =northwind_order_details[[#This Row],[unit_price]]*northwind_order_details[[#This Row],[quantity]] -> 1484 | I8: =northwind_order_details[[#This Row],[purchase amount]]*northwind_order_details[[#This Row],[discount]] -> 222.6 | J8: =northwind_order_details[[#This Row],[purchase amount]]-northwind_order_details[[#This Row],[discount amount]] -> 1261.4 | K8: =IF(northwind_order_details[[#This Row],[discount amount]]>0,"Yes","No") -> Yes | L8: =IF(northwind_order_details[[#This Row],[Revenue]]>1000,"High",IF(northwind_order_details[[#This Row],[Revenue]]>300,"Medium","Low")) -> High | M8: =IF(northwind_order_details[[#This Row],[unit_price]]=_xlfn.XLOOKUP(northwind_order_details[[#This Row],[product_id]],'Price Validation'!$D$2:$D$78,'Price Validation'!$E$2:$E$78),"Match","Mismatch") -> Mismatch | O8: Austria | P8: =SUMIF(northwind_order_details[country],$O8,northwind_order_details[Revenue]) -> 118104.94 | Q8: =AVERAGEIF(northwind_order_details[country],$O8,northwind_order_details[Revenue]) -> 1000.8893 | R8: =COUNTIF(northwind_order_details[country],O8) -> 118 | S8: =ROUND(SUMIF(northwind_order_details[country],$O8,northwind_order_details[discount amount]),2) -> 11270.19 | T8: =COUNTIFS(northwind_order_details[Type of Revenue],T$1,northwind_order_details[country],$O8) -> 38 | U8: =COUNTIFS(northwind_order_details[Type of Revenue],U$1,northwind_order_details[country],$O8) -> 51 | V8: =COUNTIFS(northwind_order_details[Type of Revenue],V$1,northwind_order_details[country],$O8) -> 29 | W8: =COUNTIFS(northwind_order_details[Price reconciliation],"Match",northwind_order_details[country],$O8) -> 37 | X8: =COUNTIFS(northwind_order_details[Price reconciliation],"Mismatch",northwind_order_details[country],$O8) -> 81
A9: 10250 | B9: 65 | C9: 16.8 | D9: 15 | E9: 0.15 | F9: =_xlfn.XLOOKUP(northwind_order_details[[#This Row],[order_id]],northwind_orders[order_id],northwind_orders[ship_country]) -> Brazil | G9: =INDEX(northwind_orders[],MATCH(northwind_order_details[[#This Row],[order_id]], northwind_orders[order_id], 0), MATCH("employee_id", northwind_orders[#Headers], 0)) -> 4 | H9: =northwind_order_details[[#This Row],[unit_price]]*northwind_order_details[[#This Row],[quantity]] -> 252 | I9: =northwind_order_details[[#This Row],[purchase amount]]*northwind_order_details[[#This Row],[discount]] -> 37.8 | J9: =northwind_order_details[[#This Row],[purchase amount]]-northwind_order_details[[#This Row],[discount amount]] -> 214.2 | K9: =IF(northwind_order_details[[#This Row],[discount amount]]>0,"Yes","No") -> Yes | L9: =IF(northwind_order_details[[#This Row],[Revenue]]>1000,"High",IF(northwind_order_details[[#This Row],[Revenue]]>300,"Medium","Low")) -> Low | M9: =IF(northwind_order_details[[#This Row],[unit_price]]=_xlfn.XLOOKUP(northwind_order_details[[#This Row],[product_id]],'Price Validation'!$D$2:$D$78,'Price Validation'!$E$2:$E$78),"Match","Mismatch") -> Mismatch | O9: Mexico | P9: =SUMIF(northwind_order_details[country],$O9,northwind_order_details[Revenue]) -> 23282.078 | Q9: =AVERAGEIF(northwind_order_details[country],$O9,northwind_order_details[Revenue]) -> 332.60111 | R9: =COUNTIF(northwind_order_details[country],O9) -> 70 | S9: =ROUND(SUMIF(northwind_order_details[country],$O9,northwind_order_details[discount amount]),2) -> 491.37 | T9: =COUNTIFS(northwind_order_details[Type of Revenue],T$1,northwind_order_details[country],$O9) -> 2 | U9: =COUNTIFS(northwind_order_details[Type of Revenue],U$1,northwind_order_details[country],$O9) -> 27 | V9: =COUNTIFS(northwind_order_details[Type of Revenue],V$1,northwind_order_details[country],$O9) -> 41 | W9: =COUNTIFS(northwind_order_details[Price reconciliation],"Match",northwind_order_details[country],$O9) -> 23 | X9: =COUNTIFS(northwind_order_details[Price reconciliation],"Mismatch",northwind_order_details[country],$O9) -> 47
A10: 10251 | B10: 22 | C10: 16.8 | D10: 6 | E10: 0.05 | F10: =_xlfn.XLOOKUP(northwind_order_details[[#This Row],[order_id]],northwind_orders[order_id],northwind_orders[ship_country]) -> France | G10: =INDEX(northwind_orders[],MATCH(northwind_order_details[[#This Row],[order_id]], northwind_orders[order_id], 0), MATCH("employee_id", northwind_orders[#Headers], 0)) -> 3 | H10: =northwind_order_details[[#This Row],[unit_price]]*northwind_order_details[[#This Row],[quantity]] -> 100.8 | I10: =northwind_order_details[[#This Row],[purchase amount]]*northwind_order_details[[#This Row],[discount]] -> 5.04 | J10: =northwind_order_details[[#This Row],[purchase amount]]-northwind_order_details[[#This Row],[discount amount]] -> 95.76 | K10: =IF(northwind_order_details[[#This Row],[discount amount]]>0,"Yes","No") -> Yes | L10: =IF(northwind_order_details[[#This Row],[Revenue]]>1000,"High",IF(northwind_order_details[[#This Row],[Revenue]]>300,"Medium","Low")) -> Low | M10: =IF(northwind_order_details[[#This Row],[unit_price]]=_xlfn.XLOOKUP(northwind_order_details[[#This Row],[product_id]],'Price Validation'!$D$2:$D$78,'Price Validation'!$E$2:$E$78),"Match","Mismatch") -> Mismatch | O10: USA | P10: =SUMIF(northwind_order_details[country],$O10,northwind_order_details[Revenue]) -> 243618.89 | Q10: =AVERAGEIF(northwind_order_details[country],$O10,northwind_order_details[Revenue]) -> 749.59658 | R10: =COUNTIF(northwind_order_details[country],O10) -> 325 | S10: =ROUND(SUMIF(northwind_order_details[country],$O10,northwind_order_details[discount amount]),2) -> 17863.49 | T10: =COUNTIFS(northwind_order_details[Type of Revenue],T$1,northwind_order_details[country],$O10) -> 67 | U10: =COUNTIFS(northwind_order_details[Type of Revenue],U$1,northwind_order_details[country],$O10) -> 133 | V10: =COUNTIFS(northwind_order_details[Type of Revenue],V$1,northwind_order_details[country],$O10) -> 125 | W10: =COUNTIFS(northwind_order_details[Price reconciliation],"Match",northwind_order_details[country],$O10) -> 126 | X10: =COUNTIFS(northwind_order_details[Price reconciliation],"Mismatch",northwind_order_details[country],$O10) -> 199
A11: 10251 | B11: 57 | C11: 15.6 | D11: 15 | E11: 0.05 | F11: =_xlfn.XLOOKUP(northwind_order_details[[#This Row],[order_id]],northwind_orders[order_id],northwind_orders[ship_country]) -> France | G11: =INDEX(northwind_orders[],MATCH(northwind_order_details[[#This Row],[order_id]], northwind_orders[order_id], 0), MATCH("employee_id", northwind_orders[#Headers], 0)) -> 3 | H11: =northwind_order_details[[#This Row],[unit_price]]*northwind_order_details[[#This Row],[quantity]] -> 234 | I11: =northwind_order_details[[#This Row],[purchase amount]]*northwind_order_details[[#This Row],[discount]] -> 11.7 | J11: =northwind_order_details[[#This Row],[purchase amount]]-northwind_order_details[[#This Row],[discount amount]] -> 222.3 | K11: =IF(northwind_order_details[[#This Row],[discount amount]]>0,"Yes","No") -> Yes | L11: =IF(northwind_order_details[[#This Row],[Revenue]]>1000,"High",IF(northwind_order_details[[#This Row],[Revenue]]>300,"Medium","Low")) -> Low | M11: =IF(northwind_order_details[[#This Row],[unit_price]]=_xlfn.XLOOKUP(northwind_order_details[[#This Row],[product_id]],'Price Validation'!$D$2:$D$78,'Price Validation'!$E$2:$E$78),"Match","Mismatch") -> Mismatch | O11: Sweden | P11: =SUMIF(northwind_order_details[country],$O11,northwind_order_details[Revenue]) -> 54495.14 | Q11: =AVERAGEIF(northwind_order_details[country],$O11,northwind_order_details[Revenue]) -> 561.80557 | R11: =COUNTIF(northwind_order_details[country],O11) -> 97 | S11: =ROUND(SUMIF(northwind_order_details[country],$O11,northwind_order_details[discount amount]),2) -> 5028.56 | T11: =COUNTIFS(northwind_order_details[Type of Revenue],T$1,northwind_order_details[country],$O11) -> 11 | U11: =COUNTIFS(northwind_order_details[Type of Revenue],U$1,northwind_order_details[country],$O11) -> 34 | V11: =COUNTIFS(northwind_order_details[Type of Revenue],V$1,northwind_order_details[country],$O11) -> 52 | W11: =COUNTIFS(northwind_order_details[Price reconciliation],"Match",northwind_order_details[country],$O11) -> 36 | X11: =COUNTIFS(northwind_order_details[Price reconciliation],"Mismatch",northwind_order_details[country],$O11) -> 61
A12: 10251 | B12: 65 | C12: 16.8 | D12: 20 | E12: 0 | F12: =_xlfn.XLOOKUP(northwind_order_details[[#This Row],[order_id]],northwind_orders[order_id],northwind_orders[ship_country]) -> France | G12: =INDEX(northwind_orders[],MATCH(northwind_order_details[[#This Row],[order_id]], northwind_orders[order_id], 0), MATCH("employee_id", northwind_orders[#Headers], 0)) -> 3 | H12: =northwind_order_details[[#This Row],[unit_price]]*northwind_order_details[[#This Row],[quantity]] -> 336 | I12: =northwind_order_details[[#This Row],[purchase amount]]*northwind_order_details[[#This Row],[discount]] -> 0 | J12: =northwind_order_details[[#This Row],[purchase amount]]-northwind_order_details[[#This Row],[discount amount]] -> 336 | K12: =IF(northwind_order_details[[#This Row],[discount amount]]>0,"Yes","No") -> No | L12: =IF(northwind_order_details[[#This Row],[Revenue]]>1000,"High",IF(northwind_order_details[[#This Row],[Revenue]]>300,"Medium","Low")) -> Medium | M12: =IF(northwind_order_details[[#This Row],[unit_price]]=_xlfn.XLOOKUP(northwind_order_details[[#This Row],[product_id]],'Price Validation'!$D$2:$D$78,'Price Validation'!$E$2:$E$78),"Match","Mismatch") -> Mismatch | O12: Finland | P12: =SUMIF(northwind_order_details[country],$O12,northwind_order_details[Revenue]) -> 18810.052 | Q12: =AVERAGEIF(northwind_order_details[country],$O12,northwind_order_details[Revenue]) -> 348.33431 | R12: =COUNTIF(northwind_order_details[country],O12) -> 54 | S12: =ROUND(SUMIF(northwind_order_details[country],$O12,northwind_order_details[discount amount]),2) -> 968.4 | T12: =COUNTIFS(northwind_order_details[Type of Revenue],T$1,northwind_order_details[country],$O12) -> 3 | U12: =COUNTIFS(northwind_order_details[Type of Revenue],U$1,northwind_order_details[country],$O12) -> 22 | V12: =COUNTIFS(northwind_order_details[Type of Revenue],V$1,northwind_order_details[country],$O12) -> 29 | W12: =COUNTIFS(northwind_order_details[Price reconciliation],"Match",northwind_order_details[country],$O12) -> 14 | X12: =COUNTIFS(northwind_order_details[Price reconciliation],"Mismatch",northwind_order_details[country],$O12) -> 40
A13: 10252 | B13: 20 | C13: 64.8 | D13: 40 | E13: 0.05 | F13: =_xlfn.XLOOKUP(northwind_order_details[[#This Row],[order_id]],northwind_orders[order_id],northwind_orders[ship_country]) -> Belgium | G13: =INDEX(northwind_orders[],MATCH(northwind_order_details[[#This Row],[order_id]], northwind_orders[order_id], 0), MATCH("employee_id", northwind_orders[#Headers], 0)) -> 4 | H13: =northwind_order_details[[#This Row],[unit_price]]*northwind_order_details[[#This Row],[quantity]] -> 2592 | I13: =northwind_order_details[[#This Row],[purchase amount]]*northwind_order_details[[#This Row],[discount]] -> 129.6 | J13: =northwind_order_details[[#This Row],[purchase amount]]-northwind_order_details[[#This Row],[discount amount]] -> 2462.4 | K13: =IF(northwind_order_details[[#This Row],[discount amount]]>0,"Yes","No") -> Yes | L13: =IF(northwind_order_details[[#This Row],[Revenue]]>1000,"High",IF(northwind_order_details[[#This Row],[Revenue]]>300,"Medium","Low")) -> High | M13: =IF(northwind_order_details[[#This Row],[unit_price]]=_xlfn.XLOOKUP(northwind_order_details[[#This Row],[product_id]],'Price Validation'!$D$2:$D$78,'Price Validation'!$E$2:$E$78),"Match","Mismatch") -> Mismatch | O13: Italy | P13: =SUMIF(northwind_order_details[country],$O13,northwind_order_details[Revenue]) -> 15363.755 | Q13: =AVERAGEIF(northwind_order_details[country],$O13,northwind_order_details[Revenue]) -> 301.2501 | R13: =COUNTIF(northwind_order_details[country],O13) -> 51 | S13: =ROUND(SUMIF(northwind_order_details[country],$O13,northwind_order_details[discount amount]),2) -> 833.4 | T13: =COUNTIFS(northwind_order_details[Type of Revenue],T$1,northwind_order_details[country],$O13) -> 1 | U13: =COUNTIFS(northwind_order_details[Type of Revenue],U$1,northwind_order_details[country],$O13) -> 19 | V13: =COUNTIFS(northwind_order_details[Type of Revenue],V$1,northwind_order_details[country],$O13) -> 31 | W13: =COUNTIFS(northwind_order_details[Price reconciliation],"Match",northwind_order_details[country],$O13) -> 15 | X13: =COUNTIFS(northwind_order_details[Price reconciliation],"Mismatch",northwind_order_details[country],$O13) -> 36
A14: 10252 | B14: 33 | C14: 2 | D14: 25 | E14: 0.05 | F14: =_xlfn.XLOOKUP(northwind_order_details[[#This Row],[order_id]],northwind_orders[order_id],northwind_orders[ship_country]) -> Belgium | G14: =INDEX(northwind_orders[],MATCH(northwind_order_details[[#This Row],[order_id]], northwind_orders[order_id], 0), MATCH("employee_id", northwind_orders[#Headers], 0)) -> 4 | H14: =northwind_order_details[[#This Row],[unit_price]]*northwind_order_details[[#This Row],[quantity]] -> 50 | I14: =northwind_order_details[[#This Row],[purchase amount]]*northwind_order_details[[#This Row],[discount]] -> 2.5 | J14: =northwind_order_details[[#This Row],[purchase amount]]-northwind_order_details[[#This Row],[discount amount]] -> 47.5 | K14: =IF(northwind_order_details[[#This Row],[discount amount]]>0,"Yes","No") -> Yes | L14: =IF(northwind_order_details[[#This Row],[Revenue]]>1000,"High",IF(northwind_order_details[[#This Row],[Revenue]]>300,"Medium","Low")) -> Low | M14: =IF(northwind_order_details[[#This Row],[unit_price]]=_xlfn.XLOOKUP(northwind_order_details[[#This Row],[product_id]],'Price Validation'!$D$2:$D$78,'Price Validation'!$E$2:$E$78),"Match","Mismatch") -> Mismatch | O14: Spain | P14: =SUMIF(northwind_order_details[country],$O14,northwind_order_details[Revenue]) -> 17983.2 | Q14: =AVERAGEIF(northwind_order_details[country],$O14,northwind_order_details[Revenue]) -> 333.02222 | R14: =COUNTIF(northwind_order_details[country],O14) -> 54 | S14: =ROUND(SUMIF(northwind_order_details[country],$O14,northwind_order_details[discount amount]),2) -> 1448.69 | T14: =COUNTIFS(northwind_order_details[Type of Revenue],T$1,northwind_order_details[country],$O14) -> 4 | U14: =COUNTIFS(northwind_order_details[Type of Revenue],U$1,northwind_order_details[country],$O14) -> 12 | V14: =COUNTIFS(northwind_order_details[Type of Revenue],V$1,northwind_order_details[country],$O14) -> 38 | W14: =COUNTIFS(northwind_order_details[Price reconciliation],"Match",northwind_order_details[country],$O14) -> 15 | X14: =COUNTIFS(northwind_order_details[Price reconciliation],"Mismatch",northwind_order_details[country],$O14) -> 39
A15: 10252 | B15: 60 | C15: 27.2 | D15: 40 | E15: 0 | F15: =_xlfn.XLOOKUP(northwind_order_details[[#This Row],[order_id]],northwind_orders[order_id],northwind_orders[ship_country]) -> Belgium | G15: =INDEX(northwind_orders[],MATCH(northwind_order_details[[#This Row],[order_id]], northwind_orders[order_id], 0), MATCH("employee_id", northwind_orders[#Headers], 0)) -> 4 | H15: =northwind_order_details[[#This Row],[unit_price]]*northwind_order_details[[#This Row],[quantity]] -> 1088 | I15: =northwind_order_details[[#This Row],[purchase amount]]*northwind_order_details[[#This Row],[discount]] -> 0 | J15: =northwind_order_details[[#This Row],[purchase amount]]-northwind_order_details[[#This Row],[discount amount]] -> 1088 | K15: =IF(northwind_order_details[[#This Row],[discount amount]]>0,"Yes","No") -> No | L15: =IF(northwind_order_details[[#This Row],[Revenue]]>1000,"High",IF(northwind_order_details[[#This Row],[Revenue]]>300,"Medium","Low")) -> High | M15: =IF(northwind_order_details[[#This Row],[unit_price]]=_xlfn.XLOOKUP(northwind_order_details[[#This Row],[product_id]],'Price Validation'!$D$2:$D$78,'Price Validation'!$E$2:$E$78),"Match","Mismatch") -> Mismatch | O15: UK | P15: =SUMIF(northwind_order_details[country],$O15,northwind_order_details[Revenue]) -> 58971.31 | Q15: =AVERAGEIF(northwind_order_details[country],$O15,northwind_order_details[Revenue]) -> 436.82452 | R15: =COUNTIF(northwind_order_details[country],O15) -> 135 | S15: =ROUND(SUMIF(northwind_order_details[country],$O15,northwind_order_details[discount amount]),2) -> 1645.2 | T15: =COUNTIFS(northwind_order_details[Type of Revenue],T$1,northwind_order_details[country],$O15) -> 14 | U15: =COUNTIFS(northwind_order_details[Type of Revenue],U$1,northwind_order_details[country],$O15) -> 49 | V15: =COUNTIFS(northwind_order_details[Type of Revenue],V$1,northwind_order_details[country],$O15) -> 72 | W15: =COUNTIFS(northwind_order_details[Price reconciliation],"Match",northwind_order_details[country],$O15) -> 31 | X15: =COUNTIFS(northwind_order_details[Price reconciliation],"Mismatch",northwind_order_details[country],$O15) -> 104
A16: 10253 | B16: 31 | C16: 10 | D16: 20 | E16: 0 | F16: =_xlfn.XLOOKUP(northwind_order_details[[#This Row],[order_id]],northwind_orders[order_id],northwind_orders[ship_country]) -> Brazil | G16: =INDEX(northwind_orders[],MATCH(northwind_order_details[[#This Row],[order_id]], northwind_orders[order_id], 0), MATCH("employee_id", northwind_orders[#Headers], 0)) -> 3 | H16: =northwind_order_details[[#This Row],[unit_price]]*northwind_order_details[[#This Row],[quantity]] -> 200 | I16: =northwind_order_details[[#This Row],[purchase amount]]*northwind_order_details[[#This Row],[discount]] -> 0 | J16: =northwind_order_details[[#This Row],[purchase amount]]-northwind_order_details[[#This Row],[discount amount]] -> 200 | K16: =IF(northwind_order_details[[#This Row],[discount amount]]>0,"Yes","No") -> No | L16: =IF(northwind_order_details[[#This Row],[Revenue]]>1000,"High",IF(northwind_order_details[[#This Row],[Revenue]]>300,"Medium","Low")) -> Low | M16: =IF(northwind_order_details[[#This Row],[unit_price]]=_xlfn.XLOOKUP(northwind_order_details[[#This Row],[product_id]],'Price Validation'!$D$2:$D$78,'Price Validation'!$E$2:$E$78),"Match","Mismatch") -> Mismatch | O16: Portugal | P16: =SUMIF(northwind_order_details[country],$O16,northwind_order_details[Revenue]) -> 11472.362 | Q16: =AVERAGEIF(northwind_order_details[country],$O16,northwind_order_details[Revenue]) -> 382.41208 | R16: =COUNTIF(northwind_order_details[country],O16) -> 30 | S16: =ROUND(SUMIF(northwind_order_details[country],$O16,northwind_order_details[discount amount]),2) -> 996.29 | T16: =COUNTIFS(northwind_order_details[Type of Revenue],T$1,northwind_order_details[country],$O16) -> 2 | U16: =COUNTIFS(northwind_order_details[Type of Revenue],U$1,northwind_order_details[country],$O16) -> 11 | V16: =COUNTIFS(northwind_order_details[Type of Revenue],V$1,northwind_order_details[country],$O16) -> 17 | W16: =COUNTIFS(northwind_order_details[Price reconciliation],"Match",northwind_order_details[country],$O16) -> 5 | X16: =COUNTIFS(northwind_order_details[Price reconciliation],"Mismatch",northwind_order_details[country],$O16) -> 25
A17: 10253 | B17: 39 | C17: 14.4 | D17: 42 | E17: 0 | F17: =_xlfn.XLOOKUP(northwind_order_details[[#This Row],[order_id]],northwind_orders[order_id],northwind_orders[ship_country]) -> Brazil | G17: =INDEX(northwind_orders[],MATCH(northwind_order_details[[#This Row],[order_id]], northwind_orders[order_id], 0), MATCH("employee_id", northwind_orders[#Headers], 0)) -> 3 | H17: =northwind_order_details[[#This Row],[unit_price]]*northwind_order_details[[#This Row],[quantity]] -> 604.8 | I17: =northwind_order_details[[#This Row],[purchase amount]]*northwind_order_details[[#This Row],[discount]] -> 0 | J17: =northwind_order_details[[#This Row],[purchase amount]]-northwind_order_details[[#This Row],[discount amount]] -> 604.8 | K17: =IF(northwind_order_details[[#This Row],[discount amount]]>0,"Yes","No") -> No | L17: =IF(northwind_order_details[[#This Row],[Revenue]]>1000,"High",IF(northwind_order_details[[#This Row],[Revenue]]>300,"Medium","Low")) -> Medium | M17: =IF(northwind_order_details[[#This Row],[unit_price]]=_xlfn.XLOOKUP(northwind_order_details[[#This Row],[product_id]],'Price Validation'!$D$2:$D$78,'Price Validation'!$E$2:$E$78),"Match","Mismatch") -> Mismatch | O17: Canada | P17: =SUMIF(northwind_order_details[country],$O17,northwind_order_details[Revenue]) -> 48886.79 | Q17: =AVERAGEIF(northwind_order_details[country],$O17,northwind_order_details[Revenue]) -> 669.68205 | R17: =COUNTIF(northwind_order_details[country],O17) -> 73 | S17: =ROUND(SUMIF(northwind_order_details[country],$O17,northwind_order_details[discount amount]),2) -> 5137.81 | T17: =COUNTIFS(northwind_order_details[Type of Revenue],T$1,northwind_order_details[country],$O17) -> 12 | U17: =COUNTIFS(northwind_order_details[Type of Revenue],U$1,northwind_order_details[country],$O17) -> 29 | V17: =COUNTIFS(northwind_order_details[Type of Revenue],V$1,northwind_order_details[country],$O17) -> 32 | W17: =COUNTIFS(northwind_order_details[Price reconciliation],"Match",northwind_order_details[country],$O17) -> 15 | X17: =COUNTIFS(northwind_order_details[Price reconciliation],"Mismatch",northwind_order_details[country],$O17) -> 58
A18: 10253 | B18: 49 | C18: 16 | D18: 40 | E18: 0 | F18: =_xlfn.XLOOKUP(northwind_order_details[[#This Row],[order_id]],northwind_orders[order_id],northwind_orders[ship_country]) -> Brazil | G18: =INDEX(northwind_orders[],MATCH(northwind_order_details[[#This Row],[order_id]], northwind_orders[order_id], 0), MATCH("employee_id", northwind_orders[#Headers], 0)) -> 3 | H18: =northwind_order_details[[#This Row],[unit_price]]*northwind_order_details[[#This Row],[quantity]] -> 640 | I18: =northwind_order_details[[#This Row],[purchase amount]]*northwind_order_details[[#This Row],[discount]] -> 0 | J18: =northwind_order_details[[#This Row],[purchase amount]]-northwind_order_details[[#This Row],[discount amount]] -> 640 | K18: =IF(northwind_order_details[[#This Row],[discount amount]]>0,"Yes","No") -> No | L18: =IF(northwind_order_details[[#This Row],[Revenue]]>1000,"High",IF(northwind_order_details[[#This Row],[Revenue]]>300,"Medium","Low")) -> Medium | M18: =IF(northwind_order_details[[#This Row],[unit_price]]=_xlfn.XLOOKUP(northwind_order_details[[#This Row],[product_id]],'Price Validation'!$D$2:$D$78,'Price Validation'!$E$2:$E$78),"Match","Mismatch") -> Mismatch | O18: Denmark | P18: =SUMIF(northwind_order_details[country],$O18,northwind_order_details[Revenue]) -> 32428.938 | Q18: =AVERAGEIF(northwind_order_details[country],$O18,northwind_order_details[Revenue]) -> 720.64306 | R18: =COUNTIF(northwind_order_details[country],O18) -> 45 | S18: =ROUND(SUMIF(northwind_order_details[country],$O18,northwind_order_details[discount amount]),2) -> 2109.01 | T18: =COUNTIFS(northwind_order_details[Type of Revenue],T$1,northwind_order_details[country],$O18) -> 6 | U18: =COUNTIFS(northwind_order_details[Type of Revenue],U$1,northwind_order_details[country],$O18) -> 19 | V18: =COUNTIFS(northwind_order_details[Type of Revenue],V$1,northwind_order_details[country],$O18) -> 20 | W18: =COUNTIFS(northwind_order_details[Price reconciliation],"Match",northwind_order_details[country],$O18) -> 12 | X18: =COUNTIFS(northwind_order_details[Price reconciliation],"Mismatch",northwind_order_details[country],$O18) -> 33
A19: 10254 | B19: 24 | C19: 3.6 | D19: 15 | E19: 0.15 | F19: =_xlfn.XLOOKUP(northwind_order_details[[#This Row],[order_id]],northwind_orders[order_id],northwind_orders[ship_country]) -> Switzerland | G19: =INDEX(northwind_orders[],MATCH(northwind_order_details[[#This Row],[order_id]], northwind_orders[order_id], 0), MATCH("employee_id", northwind_orders[#Headers], 0)) -> 5 | H19: =northwind_order_details[[#This Row],[unit_price]]*northwind_order_details[[#This Row],[quantity]] -> 54 | I19: =northwind_order_details[[#This Row],[purchase amount]]*northwind_order_details[[#This Row],[discount]] -> 8.1 | J19: =northwind_order_details[[#This Row],[purchase amount]]-northwind_order_details[[#This Row],[discount amount]] -> 45.9 | K19: =IF(northwind_order_details[[#This Row],[discount amount]]>0,"Yes","No") -> Yes | L19: =IF(northwind_order_details[[#This Row],[Revenue]]>1000,"High",IF(northwind_order_details[[#This Row],[Revenue]]>300,"Medium","Low")) -> Low | M19: =IF(northwind_order_details[[#This Row],[unit_price]]=_xlfn.XLOOKUP(northwind_order_details[[#This Row],[product_id]],'Price Validation'!$D$2:$D$78,'Price Validation'!$E$2:$E$78),"Match","Mismatch") -> Mismatch | O19: Poland | P19: =SUMIF(northwind_order_details[country],$O19,northwind_order_details[Revenue]) -> 3531.95 | Q19: =AVERAGEIF(northwind_order_details[country],$O19,northwind_order_details[Revenue]) -> 220.74687 | R19: =COUNTIF(northwind_order_details[country],O19) -> 16 | S19: =ROUND(SUMIF(northwind_order_details[country],$O19,northwind_order_details[discount amount]),2) -> 0 | T19: =COUNTIFS(northwind_order_details[Type of Revenue],T$1,northwind_order_details[country],$O19) -> 0 | U19: =COUNTIFS(northwind_order_details[Type of Revenue],U$1,northwind_order_details[country],$O19) -> 3 | V19: =COUNTIFS(northwind_order_details[Type of Revenue],V$1,northwind_order_details[country],$O19) -> 13 | W19: =COUNTIFS(northwind_order_details[Price reconciliation],"Match",northwind_order_details[country],$O19) -> 7 | X19: =COUNTIFS(northwind_order_details[Price reconciliation],"Mismatch",northwind_order_details[country],$O19) -> 9
A20: 10254 | B20: 55 | C20: 19.2 | D20: 21 | E20: 0.15 | F20: =_xlfn.XLOOKUP(northwind_order_details[[#This Row],[order_id]],northwind_orders[order_id],northwind_orders[ship_country]) -> Switzerland | G20: =INDEX(northwind_orders[],MATCH(northwind_order_details[[#This Row],[order_id]], northwind_orders[order_id], 0), MATCH("employee_id", northwind_orders[#Headers], 0)) -> 5 | H20: =northwind_order_details[[#This Row],[unit_price]]*northwind_order_details[[#This Row],[quantity]] -> 403.2 | I20: =northwind_order_details[[#This Row],[purchase amount]]*northwind_order_details[[#This Row],[discount]] -> 60.48 | J20: =northwind_order_details[[#This Row],[purchase amount]]-northwind_order_details[[#This Row],[discount amount]] -> 342.72 | K20: =IF(northwind_order_details[[#This Row],[discount amount]]>0,"Yes","No") -> Yes | L20: =IF(northwind_order_details[[#This Row],[Revenue]]>1000,"High",IF(northwind_order_details[[#This Row],[Revenue]]>300,"Medium","Low")) -> Medium | M20: =IF(northwind_order_details[[#This Row],[unit_price]]=_xlfn.XLOOKUP(northwind_order_details[[#This Row],[product_id]],'Price Validation'!$D$2:$D$78,'Price Validation'!$E$2:$E$78),"Match","Mismatch") -> Mismatch | O20: Norway | P20: =SUMIF(northwind_order_details[country],$O20,northwind_order_details[Revenue]) -> 5735.15 | Q20: =AVERAGEIF(northwind_order_details[country],$O20,northwind_order_details[Revenue]) -> 358.44688 | R20: =COUNTIF(northwind_order_details[country],O20) -> 16 | S20: =ROUND(SUMIF(northwind_order_details[country],$O20,northwind_order_details[discount amount]),2) -> 0 | T20: =COUNTIFS(northwind_order_details[Type of Revenue],T$1,northwind_order_details[country],$O20) -> 1 | U20: =COUNTIFS(northwind_order_details[Type of Revenue],U$1,northwind_order_details[country],$O20) -> 5 | V20: =COUNTIFS(northwind_order_details[Type of Revenue],V$1,northwind_order_details[country],$O20) -> 10 | W20: =COUNTIFS(northwind_order_details[Price reconciliation],"Match",northwind_order_details[country],$O20) -> 8 | X20: =COUNTIFS(northwind_order_details[Price reconciliation],"Mismatch",northwind_order_details[country],$O20) -> 8
A21: 10254 | B21: 74 | C21: 8 | D21: 21 | E21: 0 | F21: =_xlfn.XLOOKUP(northwind_order_details[[#This Row],[order_id]],northwind_orders[order_id],northwind_orders[ship_country]) -> Switzerland | G21: =INDEX(northwind_orders[],MATCH(northwind_order_details[[#This Row],[order_id]], northwind_orders[order_id], 0), MATCH("employee_id", northwind_orders[#Headers], 0)) -> 5 | H21: =northwind_order_details[[#This Row],[unit_price]]*northwind_order_details[[#This Row],[quantity]] -> 168 | I21: =northwind_order_details[[#This Row],[purchase amount]]*northwind_order_details[[#This Row],[discount]] -> 0 | J21: =northwind_order_details[[#This Row],[purchase amount]]-northwind_order_details[[#This Row],[discount amount]] -> 168 | K21: =IF(northwind_order_details[[#This Row],[discount amount]]>0,"Yes","No") -> No | L21: =IF(northwind_order_details[[#This Row],[Revenue]]>1000,"High",IF(northwind_order_details[[#This Row],[Revenue]]>300,"Medium","Low")) -> Low | M21: =IF(northwind_order_details[[#This Row],[unit_price]]=_xlfn.XLOOKUP(northwind_order_details[[#This Row],[product_id]],'Price Validation'!$D$2:$D$78,'Price Validation'!$E$2:$E$78),"Match","Mismatch") -> Mismatch | O21: Argentina | P21: =SUMIF(northwind_order_details[country],$O21,northwind_order_details[Revenue]) -> 7738.1 | Q21: =AVERAGEIF(northwind_order_details[country],$O21,northwind_order_details[Revenue]) -> 257.93667 | R21: =COUNTIF(northwind_order_details[country],O21) -> 30 | S21: =ROUND(SUMIF(northwind_order_details[country],$O21,northwind_order_details[discount amount]),2) -> 0 | T21: =COUNTIFS(northwind_order_details[Type of Revenue],T$1,northwind_order_details[country],$O21) -> 1 | U21: =COUNTIFS(northwind_order_details[Type of Revenue],U$1,northwind_order_details[country],$O21) -> 8 | V21: =COUNTIFS(northwind_order_details[Type of Revenue],V$1,northwind_order_details[country],$O21) -> 21 | W21: =COUNTIFS(northwind_order_details[Price reconciliation],"Match",northwind_order_details[country],$O21) -> 11 | X21: =COUNTIFS(northwind_order_details[Price reconciliation],"Mismatch",northwind_order_details[country],$O21) -> 19
